Workbook

Sheet Summary
A1: Station House Express - store financials at a glance
A2: BBQ + Cubans counter: lunch 11-2:30, catering pickups until 7 pm, 1,500 sq ft, 32 seats, 5 days/week, meats from the commissary at cost + 25%. Prepared Oct 27, 2026.
B4: Conservative | C4: Base | D4: Strong
A5: Sales
A6: Sales per day | B6: ='Sales & P&L'!G25 -> 2339.675 | C6: ='Sales & P&L'!H25 -> 3599.5 | D6: ='Sales & P&L'!I25 -> 5039.3
A7: Sales per week | B7: ='Sales & P&L'!G27 -> 11698.375 | C7: ='Sales & P&L'!H27 -> 17997.5 | D7: ='Sales & P&L'!I27 -> 25196.5
A8: Sales per month | B8: ='Sales & P&L'!G36 -> 50653.964 | C8: ='Sales & P&L'!H36 -> 77929.175 | D8: ='Sales & P&L'!I36 -> 109100.85
A9: of which evening catering pickups | B9: ='Sales & P&L'!G35 -> 10683.842 | C9: ='Sales & P&L'!H35 -> 16436.68 | D9: ='Sales & P&L'!I35 -> 23011.352
A10: Costs (% of sales)
A11: Cost of goods (meat at transfer price + food + packaging) | B11: ='Sales & P&L'!G41/'Sales & P&L'!G36 -> 0.34471446 | C11: ='Sales & P&L'!H41/'Sales & P&L'!H36 -> 0.34471446 | D11: ='Sales & P&L'!I41/'Sales & P&L'!I36 -> 0.34471446
A12: Labor | B12: ='Sales & P&L'!G48/'Sales & P&L'!G36 -> 0.31831389 | C12: ='Sales & P&L'!H48/'Sales & P&L'!H36 -> 0.20690403 | D12: ='Sales & P&L'!I48/'Sales & P&L'!I36 -> 0.14778859
A13: Prime cost (COGS + labor) - target under 60% | B13: ='Sales & P&L'!G50 -> 0.66302834 | C13: ='Sales & P&L'!H50 -> 0.55161848 | D13: ='Sales & P&L'!I50 -> 0.49250305
A14: Occupancy | B14: ='Sales & P&L'!G54/'Sales & P&L'!G36 -> 0.18359866 | C14: ='Sales & P&L'!H54/'Sales & P&L'!H36 -> 0.11933913 | D14: ='Sales & P&L'!I54/'Sales & P&L'!I36 -> 0.085242236
A15: Profit
A16: Store EBITDA per month | B16: ='Sales & P&L'!G68 -> 1762.156 | C16: ='Sales & P&L'!H68 -> 18298.722 | D16: ='Sales & P&L'!I68 -> 37197.655
A17: Store EBITDA margin | B17: ='Sales & P&L'!G69 -> 0.034788116 | C17: ='Sales & P&L'!H69 -> 0.23481222 | D17: ='Sales & P&L'!I69 -> 0.34094745
A18: Commissary profit from this store per month (meat markup) | B18: ='Sales & P&L'!G72 -> 2018.173 | C18: ='Sales & P&L'!H72 -> 3104.8815 | D18: ='Sales & P&L'!I72 -> 4346.8341
A19: Combined Station House profit per month | B19: ='Sales & P&L'!G73 -> 3780.329 | C19: ='Sales & P&L'!H73 -> 21403.604 | D19: ='Sales & P&L'!I73 -> 41544.489
A20: Payback on startup cost (months) | B20: ='Sales & P&L'!G74 -> 264.57017 | C20: ='Sales & P&L'!H74 -> 25.477949 | D20: ='Sales & P&L'!I74 -> 12.533422
A21: Who makes money (per year)
A22: Investor share of store profit | B22: ='Who Makes Money'!B13 -> 2037.3115 | C22: ='Who Makes Money'!C13 -> 134071.12 | D22: ='Who Makes Money'!D13 -> 284966.89
A23: Investor cash-on-cash return | B23: ='Who Makes Money'!B14 -> 0.004369907 | C23: ='Who Makes Money'!C14 -> 0.28757425 | D23: ='Who Makes Money'!D14 -> 0.61123635
A24: Station House total (fee + ownership share + commissary markup) | B24: ='Who Makes Money'!B21 -> 43326.636 | C24: ='Who Makes Money'!C21 -> 122772.13 | D24: ='Who Makes Money'!D21 -> 213566.98
A25: One-number answers
A26: Startup cost - raw shell, 1st generation | C26: ='Startup Budget'!$F$47 -> 725305.71
A27: Startup cost - former restaurant, 2nd generation | C27: ='Startup Budget'!$G$47 -> 466213.91
A28: Startup cost used in this plan | C28: ='Startup Budget'!$F$50 -> 466213.91
A29: Break-even sales per day | C29: ='Break-Even'!$B$19 -> 2205.4266
A30: Break-even sales per week | C30: ='Break-Even'!$B$18 -> 11027.133
A31: Break-even tickets per day | C31: ='Break-Even'!$B$20 -> 47.124499
A32: Break-even per day incl. 20%/yr investor return | C32: ='Break-Even'!$B$28 -> 2797.3954
A33: Food + packaging cost: 5-Alarm Sampler 2-3 | C33: ='Menu Costing'!E43/'Menu Costing'!E44 -> 0.31957481
A34: Food + packaging cost: 5-Alarm Sampler 5-6 | C34: ='Menu Costing'!F43/'Menu Costing'!F44 -> 0.35865499
A35: Food + packaging cost: Brisket Cuban | C35: ='Menu Costing'!G43/'Menu Costing'!G44 -> 0.31725231
A36: Food + packaging cost: Smokin' Cuban | C36: ='Menu Costing'!H43/'Menu Costing'!H44 -> 0.25149474
A37: Food + packaging cost: fountain drink | C37: ='Menu Costing'!S43/'Menu Costing'!S44 -> 0.17531773
A38: Food + packaging cost: cornbread + tallow butter | C38: ='Menu Costing'!T43/'Menu Costing'!T44 -> 0.27375091
A39: Food + packaging cost: Party Sampler Feeds 20 | C39: ='Menu Costing'!V43/'Menu Costing'!V44 -> 0.42023966
A40: Annual meat savings going direct, base case (store only) | C40: ='Direct vs Distributor'!$I$11 -> 18929.172
A41: Annual meat savings going direct, base case (whole business) | C41: ='Direct vs Distributor'!$I$15 -> 56787.515
...

Sheet Assumptions
A1: Assumptions - every input in one place
A2: Blue = input you can change. Yellow = key assumption to confirm. Black = formula. Green = link to another tab.
A4: Operating calendar
A5: Days open per week (lunch only) | B5: 5 | C5: days | D5: From Anthony: 5-day week, lunch only (2 days off).
A6: Weeks per month | B6: 4.33 | C6: weeks | D6: 52 weeks / 12 months.
A7: Scenario volume: Conservative (x base) | B7: 0.65 | D7: Slow ramp / first 90 days.
A8: Scenario volume: Base (x base) | B8: 1 | D8: Base day = ~$2,800 sales (see Sales & P&L daily units).
A9: Scenario volume: Strong (x base) | B9: 1.4 | D9: Comparable to a strong Seminole Heights Saturday (~$2.9K) every day.
A10: Average ticket (Seminole Heights actual) | B10: 46.8 | C10: $ | D10: Square, Seminole Heights, Sep 18 - Oct 27, 2026: 1,000 completed orders, $46,804.
A11: Commissary (meats only)
A12: Commissary markup on meats (cost + %) | B12: 0.25 | D12: From Anthony: cost + 25%. Restaurant buys all other food and supplies itself.
A13: Commissary labor for this store (hours per week) | B13: 20 | C13: hrs/wk | D13: From Anthony: about 20 hours a week.
A14: Commissary pitmaster / prep hourly rate | B14: 18 | C14: $/hr | D14: Estimate - set to what you pay at the commissary.
A15: Wood cost per smoke (one smoker load) | B15: 15 | C15: $ | D15: From Anthony: ~$15 a smoke.
A16: Smokes per smoke day (2 smokers x 2 a day) | B16: 4 | D16: From Anthony: two smokers, twice a day.
A17: Smoke days per week for this store | B17: 3 | C17: days | D17: Sun / Mon / Tue cadence. Change if the store volume needs more or fewer.
A18: Vac bags, foil, labels per raw lb processed | B18: 0.08 | C18: $/lb | D18: Estimate.
A19: Deliveries per week (1 scheduled + emergencies) | B19: 1.5 | C19: runs | D19: From Anthony: one delivery a week plus an emergency run when needed (assumed every other week).
A20: Cost per delivery run (driver time + fuel + vehicle) | B20: 60 | C20: $/run | D20: Estimate: ~2 hrs driver + fuel/wear.
A21: Warehouse / commissary rent (monthly) | B21: 10100 | C21: $/mo | D21: From Anthony: $10,100/month.
A22: Share of warehouse rent charged to this store | B22: 0 | D22: Input. 0% = the store is extra volume through a commissary you already pay for (catering covers the rent). Try 10-20% to see a fully loaded view.
A23: Commissary process cost per raw lb (calculated on Commissary P&L) | B23: ='Commissary P&L'!$B$20 -> 1.2120984 | C23: $/lb | D23: Labor + wood + bags + delivery divided by raw pounds processed for this store. Feeds the transfer price.
A24: USDA wholesale benchmarks (what packers sell at, full truckloads)
A25: Brisket, whole packer IMPS 120, Prime | B25: 4.92 | C25: $/lb | D25: USDA AMS LM_XB456 weekly Prime, Oct 19 2026, avg $492/cwt (range $458-$634). Choice was $3.87 (LM_XB403, Oct 26).
A26: Pork butt, 1/4 trim | B26: 1.23 | C26: $/lb | D26: USDA pork cutout morning report Oct 13 2026 via IndexBox write-up (USDA report itself not reached).
A27: Spare ribs, trimmed medium | B27: 1.69 | C27: $/lb | D27: Same USDA pork report, Oct 13 2026.
A28: Pork belly, skin-on 10-12 lb | B28: 2.38 | C28: $/lb | D28: Same USDA pork report. Skinless 13-17 lb was $1.16 but skin-on is closer to what burnt ends use.
A29: Chicken leg quarters, bulk | B29: 0.529 | C29: $/lb | D29: USDA weekly chicken report, Oct 23 2026, avg $52.9/cwt.
A30: Meat prices you pay today (Station House order guide)
A31: Brisket, Prime whole packer | B31: 5.72 | C31: $/lb | D31: US Foods Prime, $5.72/lb (Anthony, Oct 27). Order guide still lists Centerpoint at $7.82/lb.
A32: Pork butt, cs 4x14# | B32: 2.07 | C32: $/lb | D32: Centerpoint, $115.92/cs.
A33: Spare ribs 5#+, cs 8/5#+ | B33: 2.89 | C33: $/lb | D33: Cheney, $115.60/cs.
A34: Pork belly skin-off | B34: 4.21 | C34: $/lb | D34: US Foods, $4.21/lb (Anthony, Oct 27).
A35: Chicken leg quarters, cs 4x10# | B35: 0.81 | C35: $/lb | D35: Centerpoint, $32.40/cs.
A36: Jalapeno cheddar sausage, cs 10# | B36: 5.89 | C36: $/lb | D36: Centerpoint, $58.90/cs.
A37: Expected savings buying direct vs today (base case) | B37: 0.15 | D37: Estimate. Sensitivity at 10% / 20% / 30% on Direct vs Distributor. Get a written packer or purveyor quote to replace this.
A38: Yields and portions
A39: Brisket cook + trim yield (raw packer to sliced) | B39: 0.5 | D39: Confirmed by Anthony: 50%.
A40: Pork butt yield (raw to pulled) | B40: 0.55 | D40: Rule of thumb 50-60%.
A41: Pork belly yield (raw to burnt ends) | B41: 0.6 | D41: Rule of thumb.
...

Sheet Meat Cost & Transfer
A1: Meat cost and commissary transfer price
A2: Commissary buys raw meat, smokes, chills and vac-packs it, then sells it to the store at cost + markup. Store pays the transfer price.
A4: Protein | B4: Unit sold to store | C4: USDA $/lb | D4: You pay today $/lb (order guide) | E4: Raw lb per unit | F4: Raw cost per unit | G4: Commissary process cost per unit (labor, wood, bags, delivery) | H4: Commissary cost per unit | I4: Markup | J4: Store pays (transfer) | K4: Commissary profit per unit
A5: Brisket (sliced) | B5: cooked lb | C5: =Assumptions!$B$25 -> 4.92 | D5: =Assumptions!$B$31 -> 5.72 | E5: =1/Assumptions!$B$39 -> 2 | F5: =D5*E5 -> 11.44 | G5: =E5*Assumptions!$B$23 -> 2.4241967 | H5: =F5+G5 -> 13.864197 | I5: =Assumptions!$B$12 -> 0.25 | J5: =H5*(1+I5) -> 17.330246 | K5: =J5-H5 -> 3.4660492
A6: Pulled pork | B6: cooked lb | C6: =Assumptions!$B$26 -> 1.23 | D6: =Assumptions!$B$32 -> 2.07 | E6: =1/Assumptions!$B$40 -> 1.8181818 | F6: =D6*E6 -> 3.7636364 | G6: =E6*Assumptions!$B$23 -> 2.2038152 | H6: =F6+G6 -> 5.9674516 | I6: =Assumptions!$B$12 -> 0.25 | J6: =H6*(1+I6) -> 7.4593145 | K6: =J6-H6 -> 1.4918629
A7: Pork belly burnt ends | B7: cooked lb | C7: =Assumptions!$B$28 -> 2.38 | D7: =Assumptions!$B$34 -> 4.21 | E7: =1/Assumptions!$B$41 -> 1.6666667 | F7: =D7*E7 -> 7.0166667 | G7: =E7*Assumptions!$B$23 -> 2.0201639 | H7: =F7+G7 -> 9.0368306 | I7: =Assumptions!$B$12 -> 0.25 | J7: =H7*(1+I7) -> 11.296038 | K7: =J7-H7 -> 2.2592077
A8: Spare ribs | B8: rack | C8: =Assumptions!$B$27 -> 1.69 | D8: =Assumptions!$B$33 -> 2.89 | E8: =Assumptions!$B$42 -> 3.5 | F8: =D8*E8 -> 10.115 | G8: =E8*Assumptions!$B$23 -> 4.2423443 | H8: =F8+G8 -> 14.357344 | I8: =Assumptions!$B$12 -> 0.25 | J8: =H8*(1+I8) -> 17.94668 | K8: =J8-H8 -> 3.5893361
A9: Chicken leg quarter | B9: each | C9: =Assumptions!$B$29 -> 0.529 | D9: =Assumptions!$B$35 -> 0.81 | E9: =Assumptions!$B$44 -> 0.75 | F9: =D9*E9 -> 0.6075 | G9: 0 | H9: =F9+G9 -> 0.6075 | I9: =Assumptions!$B$12 -> 0.25 | J9: =H9*(1+I9) -> 0.759375 | K9: =J9-H9 -> 0.151875 | L9: Raw on the weekly delivery; smoked fresh daily at the store
A10: Jalapeno cheddar sausage | B10: link | C10: n/a | D10: =Assumptions!$B$36 -> 5.89 | E10: =1/Assumptions!$B$45 -> 0.25 | F10: =D10*E10 -> 1.4725 | G10: =E10*Assumptions!$B$23 -> 0.30302459 | H10: =F10+G10 -> 1.7755246 | I10: =Assumptions!$B$12 -> 0.25 | J10: =H10*(1+I10) -> 2.2194057 | K10: =J10-H10 -> 0.44388115
A12: Rib bone (for samplers) | B12: bone | H12: =H8/Assumptions!$B$43 -> 1.1964454 | J12: =J8/Assumptions!$B$43 -> 1.4955567 | K12: =J12-H12 -> 0.29911134
A14: How to read this: "Store pays" is what the restaurant is charged per unit and is what Menu Costing uses. Purchase prices are what you pay today per the Station House order guide (Centerpoint / Cheney). USDA is shown only as a benchmark; see Direct vs Distributor.
A15: Brisket price warning: in late Sept 2026 USDA grocery brisket specials jumped from $5.29 to $11.05/lb and some BBQ operators saw wholesale go from <$6 to ~$8/lb (KY3, Sep 29 2026). Re-check before you sign anything.

Sheet Sides & Ingredients
A1: Sides, desserts, bread, sauces and packaging - store buys these
A2: Prices from the Station House order guide (Cheney, US Foods, La Segunda) where listed; column G says which. Lines marked Estimate are not in the order guide.
A4: House BBQ sauce (Sweet Eddie / Carolina Gold / Spicy avg) (batch yields 128 oz)
A5: Ingredient | B5: Qty / batch | C5: Unit | D5: Cost per unit | E5: Batch cost | F5: Buy as (pack) | G5: Note
A6: Ketchup, #10 can | B6: 1 | C6: can | D6: 7.8533 | E6: =B6*D6 -> 7.8533 | F6: 6 x #10 case | G6: Order guide: Cheney 6/#10 $47.12
A7: Brown sugar | B7: 2 | C7: lb | D7: 1.3372 | E7: =B7*D7 -> 2.6744 | F7: 25 lb bag | G7: Order guide: Cheney 25# $33.43
A8: Vinegar | B8: 16 | C8: oz | D8: 0.0403 | E8: =B8*D8 -> 0.6448 | F8: 4 x 1 gal | G8: Order guide: Cheney distilled 4/1gal $20.61
A9: Worcestershire | B9: 8 | C9: oz | D9: 0.12 | E9: =B9*D9 -> 0.96 | F9: 4 x 1 gal | G9: Estimate
A10: Spices / rub | B10: 1 | C10: batch | D10: 2 | E10: =B10*D10 -> 2 | F10: Flashover rub, in-house | G10: Estimate
A11: Batch cost | E11: =SUM(E6:E10) -> 14.1325
A12: Batch yield (oz) | E12: 128
A13: Cost per oz | E13: =E11/E12 -> 0.11041016
A15: Beef tallow smoked mac & cheese (batch yields 256 oz)
A16: Ingredient | B16: Qty / batch | C16: Unit | D16: Cost per unit | E16: Batch cost | F16: Buy as (pack) | G16: Note
A17: Cavatappi | B17: 4 | C17: lb | D17: 1.796 | E17: =B17*D17 -> 7.184 | F17: 4 x 5 lb | G17: Order guide: US Foods 4/5# $35.92
A18: Smoked cheddar | B18: 3 | C18: lb | D18: 5.59 | E18: =B18*D18 -> 16.77 | F18: 4 x 2.25 lb | G18: Order guide: Cheney 4/2.25# $50.31
A19: Smoked gouda | B19: 3 | C19: lb | D19: 5.27 | E19: =B19*D19 -> 15.81 | F19: 2 x 6 lb | G19: Order guide: US Foods $5.27 (listed; confirm $/lb)
A20: Whole milk | B20: 1 | C20: gal | D20: 6.6025 | E20: =B20*D20 -> 6.6025 | F20: 4 x 1 gal | G20: Order guide: Cheney 4/1gal $26.41
A21: Heavy cream | B21: 2 | C21: qt | D21: 4.6308 | E21: =B21*D21 -> 9.2616 | F21: 12 x 1 qt | G21: Order guide: Cheney 12/1qt $55.57
A22: Butter | B22: 1 | C22: lb | D22: 2.3339 | E22: =B22*D22 -> 2.3339 | F22: 36 x 1 lb | G22: Order guide: US Foods 36/1# $84.02
A23: Seasoning | B23: 1 | C23: batch | D23: 1.5 | E23: =B23*D23 -> 1.5 | G23: Estimate
A24: Batch cost | E24: =SUM(E17:E23) -> 59.462
A25: Batch yield (oz) | E25: 256
A26: Cost per oz | E26: =E24/E25 -> 0.23227344
A28: Cowboy beans (brisket) (batch yields 340 oz)
A29: Ingredient | B29: Qty / batch | C29: Unit | D29: Cost per unit | E29: Batch cost | F29: Buy as (pack) | G29: Note
A30: Baked beans, #10 can | B30: 3 | C30: can | D30: 7.6883 | E30: =B30*D30 -> 23.0649 | F30: 6 x #10 case | G30: Order guide: US Foods 6/#10 $46.13
A31: Brisket trim / burnt ends trim | B31: 2 | C31: lb | D31: 2 | E31: =B31*D31 -> 4 | F31: commissary trim (internal value) | G31: Estimate
A32: Yellow onion | B32: 1 | C32: lb | D32: 0.9 | E32: =B32*D32 -> 0.9 | F32: 50 lb sack | G32: Estimate
A33: Bell pepper | B33: 0.5 | C33: lb | D33: 1.5 | E33: =B33*D33 -> 0.75 | F33: case | G33: Estimate
A34: House BBQ sauce | B34: 32 | C34: oz | D34: ='Sides & Ingredients'!$E$13 -> 0.11041016 | E34: =B34*D34 -> 3.533125
A35: Brown sugar | B35: 1 | C35: lb | D35: 1.3372 | E35: =B35*D35 -> 1.3372 | F35: 25 lb bag | G35: Order guide: Cheney 25# $33.43
A36: Mustard / spice | B36: 1 | C36: batch | D36: 1 | E36: =B36*D36 -> 1 | G36: Estimate
A37: Batch cost | E37: =SUM(E30:E36) -> 34.585225
A38: Batch yield (oz) | E38: 340
A39: Cost per oz | E39: =E37/E38 -> 0.10172125
A41: Apple coleslaw (batch yields 160 oz)
A42: Ingredient | B42: Qty / batch | C42: Unit | D42: Cost per unit | E42: Batch cost | F42: Buy as (pack) | G42: Note
A43: Coleslaw mix | B43: 5 | C43: lb | D43: 1.5155 | E43: =B43*D43 -> 7.5775 | F43: 4 x 5 lb | G43: Order guide: Cheney 4/5# $30.31
A44: Apples | B44: 3 | C44: lb | D44: 1.4136 | E44: =B44*D44 -> 4.2408 | F44: 12 x 3 lb | G44: Order guide: Cheney 12/3# $50.89
...

Sheet Menu Costing
A1: Menu costing - plate cost of every item
A2: Each column is a menu item; each row is a component and how much of it the item uses. Plate cost = quantity x unit cost. Meats are costed at the commissary transfer price.
A4: Component | B4: Unit | C4: Category | D4: Unit cost | E4: 5-Alarm Sampler 2-3 | F4: 5-Alarm Sampler 5-6 | G4: Brisket Cuban | H4: Smokin' Cuban | I4: Pre-order Brisket /lb | J4: Pre-order Pulled Pork /lb | K4: Pre-order Spare Ribs /rack | L4: Pre-order Burnt Ends /lb | M4: Pre-order Sausage /link | N4: Pre-order Chicken LQ | O4: Mac & Cheese 6 oz | P4: Cowboy Beans 6 oz | Q4: Apple Slaw 6 oz | R4: Banana Pudding | S4: Fountain drink | T4: Cornbread + tallow butter | U4: Party Sampler Feeds 10 | V4: Party Sampler Feeds 20 | W4: Party Sampler Feeds 30 | X4: Party Sampler Feeds 50
A5: Brisket (sliced) | B5: cooked lb | C5: Meat | D5: ='Meat Cost & Transfer'!$J$5 -> 17.330246 | E5: 0.25 | F5: 0.5 | G5: 0.25 | I5: 1 | U5: 1 | V5: 2 | W5: 3 | X5: 5
A6: Pulled pork | B6: cooked lb | C6: Meat | D6: ='Meat Cost & Transfer'!$J$6 -> 7.4593145 | E6: 0.25 | F6: 0.5 | H6: 0.1875 | J6: 1 | U6: 2.5 | V6: 5 | W6: 7.5 | X6: 12.5
A7: Burnt ends | B7: cooked lb | C7: Meat | D7: ='Meat Cost & Transfer'!$J$7 -> 11.296038 | L7: 1
A8: Spare rib (bone) | B8: bone | C8: Meat | D8: ='Meat Cost & Transfer'!$J$12 -> 1.4955567 | E8: 2 | F8: 6 | K8: 12 | U8: 6 | V8: 12 | W8: 18 | X8: 24
A9: Chicken leg quarter | B9: each | C9: Meat | D9: ='Meat Cost & Transfer'!$J$9 -> 0.759375 | E9: 1 | F9: 2 | N9: 1 | U9: 3 | V9: 6 | W9: 9 | X9: 15
A10: Jalapeno cheddar sausage | B10: link | C10: Meat | D10: ='Meat Cost & Transfer'!$J$10 -> 2.2194057 | E10: 1 | F10: 2 | M10: 1 | U10: 4 | V10: 8 | W10: 12 | X10: 20
A11: Mac & cheese | B11: oz | C11: Food | D11: ='Sides & Ingredients'!$E$26 -> 0.23227344 | E11: 8 | F11: 32 | O11: 6 | U11: 128 | V11: 256 | W11: 256 | X11: 512
A12: Cowboy beans | B12: oz | C12: Food | D12: ='Sides & Ingredients'!$E$39 -> 0.10172125 | E12: 8 | F12: 16 | P12: 6 | U12: 32 | V12: 128 | W12: 128 | X12: 256
A13: Apple coleslaw | B13: oz | C13: Food | D13: ='Sides & Ingredients'!$E$51 -> 0.13104437 | Q13: 6 | U13: 32 | V13: 128 | W13: 128 | X13: 256
A14: Banana pudding | B14: cup | C14: Food | D14: ='Sides & Ingredients'!$E$62 -> 1.5534375 | R14: 1
A15: Texas toast | B15: slice | C15: Food | D15: ='Sides & Ingredients'!$D$115 -> 0.2793 | E15: 4 | F15: 6 | U15: 20 | V15: 40 | W15: 60 | X15: 100
A16: Pickles | B16: oz | C16: Food | D16: ='Sides & Ingredients'!$D$116 -> 0.1367 | E16: 1 | F16: 2 | U16: 8 | V16: 16 | W16: 32 | X16: 32
A17: Pickled onions | B17: oz | C17: Food | D17: ='Sides & Ingredients'!$E$72 -> 0.08969 | E17: 1 | F17: 2 | G17: 0.5 | U17: 8 | V17: 16 | W17: 16 | X17: 16
A18: BBQ sauce | B18: oz | C18: Food | D18: ='Sides & Ingredients'!$E$13 -> 0.11041016 | E18: 6 | F18: 6 | I18: 2 | J18: 2 | K18: 2 | U18: 16 | V18: 32 | W18: 64 | X18: 64
A19: Cuban bread | B19: each | C19: Food | D19: ='Sides & Ingredients'!$D$117 -> 0.47 | G19: 1 | H19: 1
A20: Swiss | B20: oz | C20: Food | D20: ='Sides & Ingredients'!$D$118 -> 0.2831 | G20: 1.5 | H20: 1.5
A21: Ham | B21: oz | C21: Food | D21: ='Sides & Ingredients'!$D$119 -> 0.2806 | H21: 2
A22: Salami | B22: oz | C22: Food | D22: ='Sides & Ingredients'!$D$120 -> 0.375 | H22: 1
A23: Jerk aioli | B23: oz | C23: Food | D23: ='Sides & Ingredients'!$E$82 -> 0.120725 | G23: 0.5 | H23: 0.75
A24: Guava BBQ | B24: oz | C24: Food | D24: ='Sides & Ingredients'!$E$91 -> 0.14988177 | H24: 0.5
A25: Butter | B25: oz | C25: Food | D25: ='Sides & Ingredients'!$D$121 -> 0.1459 | G25: 0.5 | H25: 0.5
A26: Fountain drink | B26: each | C26: Food | D26: ='Sides & Ingredients'!$D$128 -> 0.5242 | S26: 1
A27: Cornbread | B27: piece | C27: Food | D27: ='Sides & Ingredients'!$E$101 -> 0.5022 | T27: 1
A28: Tallow honey butter | B28: oz | C28: Food | D28: ='Sides & Ingredients'!$E$111 -> 0.12663047 | T28: 0.5
A29: Pack: sampler 2-3 | B29: each | C29: Packaging | D29: ='Sides & Ingredients'!$D$122 -> 2.326 | E29: 1
A30: Pack: sampler 5-6 | B30: each | C30: Packaging | D30: ='Sides & Ingredients'!$D$123 -> 3.858 | F30: 1
A31: Pack: Cuban | B31: each | C31: Packaging | D31: ='Sides & Ingredients'!$D$124 -> 0.302 | G31: 1 | H31: 1
A32: Pack: side cup | B32: each | C32: Packaging | D32: ='Sides & Ingredients'!$D$125 -> 0.253 | O32: 1 | P32: 1 | Q32: 1 | T32: 1
A33: Pack: pudding cup | B33: each | C33: Packaging | D33: ='Sides & Ingredients'!$D$126 -> 0.303 | R33: 1
A34: Pack: pre-order pan | B34: each | C34: Packaging | D34: ='Sides & Ingredients'!$D$127 -> 1.944 | I34: 1 | J34: 1 | K34: 1 | L34: 1
A35: Pack: Party Sampler 10 | B35: each | C35: Packaging | D35: ='Sides & Ingredients'!$D$129 -> 11.016 | U35: 1
A36: Pack: Party Sampler 20 | B36: each | C36: Packaging | D36: ='Sides & Ingredients'!$D$130 -> 19.738 | V36: 1
A37: Pack: Party Sampler 30 | B37: each | C37: Packaging | D37: ='Sides & Ingredients'!$D$131 -> 25.997 | W37: 1
A38: Pack: Party Sampler 50 | B38: each | C38: Packaging | D38: ='Sides & Ingredients'!$D$132 -> 42.347 | X38: 1
A40: Meat cost | E40: =SUMPRODUCT(($C$5:$C$38="Meat")*E$5:E$38*$D$5:$D$38) -> 12.167284 | F40: =SUMPRODUCT(($C$5:$C$38="Meat")*F$5:F$38*$D$5:$D$38) -> 27.325682 | G40: =SUMPRODUCT(($C$5:$C$38="Meat")*G$5:G$38*$D$5:$D$38) -> 4.3325615 | H40: =SUMPRODUCT(($C$5:$C$38="Meat")*H$5:H$38*$D$5:$D$38) -> 1.3986215 | I40: =SUMPRODUCT(($C$5:$C$38="Meat")*I$5:I$38*$D$5:$D$38) -> 17.330246 | J40: =SUMPRODUCT(($C$5:$C$38="Meat")*J$5:J$38*$D$5:$D$38) -> 7.4593145 | K40: =SUMPRODUCT(($C$5:$C$38="Meat")*K$5:K$38*$D$5:$D$38) -> 17.94668 | L40: =SUMPRODUCT(($C$5:$C$38="Meat")*L$5:L$38*$D$5:$D$38) -> 11.296038 | ... X40: =SUMPRODUCT(($C$5:$C$38="Meat")*X$5:X$38*$D$5:$D$38) -> 271.56476
A41: Other food cost | E41: =SUMPRODUCT(($C$5:$C$38="Food")*E$5:E$38*$D$5:$D$38) -> 4.6780084 | F41: =SUMPRODUCT(($C$5:$C$38="Food")*F$5:F$38*$D$5:$D$38) -> 11.851331 | G41: =SUMPRODUCT(($C$5:$C$38="Food")*G$5:G$38*$D$5:$D$38) -> 1.0728075 | H41: =SUMPRODUCT(($C$5:$C$38="Food")*H$5:H$38*$D$5:$D$38) -> 2.0692846 | I41: =SUMPRODUCT(($C$5:$C$38="Food")*I$5:I$38*$D$5:$D$38) -> 0.22082031 | J41: =SUMPRODUCT(($C$5:$C$38="Food")*J$5:J$38*$D$5:$D$38) -> 0.22082031 | K41: =SUMPRODUCT(($C$5:$C$38="Food")*K$5:K$38*$D$5:$D$38) -> 0.22082031 | L41: =SUMPRODUCT(($C$5:$C$38="Food")*L$5:L$38*$D$5:$D$38) -> 0 | ... X41: =SUMPRODUCT(($C$5:$C$38="Food")*X$5:X$38*$D$5:$D$38) -> 219.31769
A42: Packaging | E42: =SUMPRODUCT(($C$5:$C$38="Packaging")*E$5:E$38*$D$5:$D$38) -> 2.326 | F42: =SUMPRODUCT(($C$5:$C$38="Packaging")*F$5:F$38*$D$5:$D$38) -> 3.858 | G42: =SUMPRODUCT(($C$5:$C$38="Packaging")*G$5:G$38*$D$5:$D$38) -> 0.302 | H42: =SUMPRODUCT(($C$5:$C$38="Packaging")*H$5:H$38*$D$5:$D$38) -> 0.302 | I42: =SUMPRODUCT(($C$5:$C$38="Packaging")*I$5:I$38*$D$5:$D$38) -> 1.944 | J42: =SUMPRODUCT(($C$5:$C$38="Packaging")*J$5:J$38*$D$5:$D$38) -> 1.944 | K42: =SUMPRODUCT(($C$5:$C$38="Packaging")*K$5:K$38*$D$5:$D$38) -> 1.944 | L42: =SUMPRODUCT(($C$5:$C$38="Packaging")*L$5:L$38*$D$5:$D$38) -> 1.944 | ... X42: =SUMPRODUCT(($C$5:$C$38="Packaging")*X$5:X$38*$D$5:$D$38) -> 42.347
...

Sheet Sales & P&L
A1: Daily sales forecast and monthly P&L (3 scenarios)
A2: Base units per day are inputs (blue). Conservative and Strong scale the base by the multipliers on Assumptions.
A4: Menu item | B4: Price | C4: Base units / day (catering = per week / 5) | D4: Conservative units | E4: Strong units | G4: Revenue / day (Cons.) | H4: Revenue / day (Base) | I4: Revenue / day (Strong)
A5: 5-Alarm Sampler 2-3 | B5: =Assumptions!$B$50 -> 59.99 | C5: 14 | D5: =C5*Assumptions!$B$7 -> 9.1 | E5: =C5*Assumptions!$B$9 -> 19.6 | G5: =B5*D5 -> 545.909 | H5: =B5*C5 -> 839.86 | I5: =B5*E5 -> 1175.804
A6: 5-Alarm Sampler 5-6 | B6: =Assumptions!$B$51 -> 119.99 | C6: 3 | D6: =C6*Assumptions!$B$7 -> 1.95 | E6: =C6*Assumptions!$B$9 -> 4.2 | G6: =B6*D6 -> 233.9805 | H6: =B6*C6 -> 359.97 | I6: =B6*E6 -> 503.958
A7: Brisket Cuban | B7: =Assumptions!$B$52 -> 17.99 | C7: 22 | D7: =C7*Assumptions!$B$7 -> 14.3 | E7: =C7*Assumptions!$B$9 -> 30.8 | G7: =B7*D7 -> 257.257 | H7: =B7*C7 -> 395.78 | I7: =B7*E7 -> 554.092
A8: Smokin' Cuban | B8: =Assumptions!$B$53 -> 14.99 | C8: 25 | D8: =C8*Assumptions!$B$7 -> 16.25 | E8: =C8*Assumptions!$B$9 -> 35 | G8: =B8*D8 -> 243.5875 | H8: =B8*C8 -> 374.75 | I8: =B8*E8 -> 524.65
A9: Pre-order Brisket /lb | B9: =Assumptions!$B$54 -> 45.99 | C9: 5 | D9: =C9*Assumptions!$B$7 -> 3.25 | E9: =C9*Assumptions!$B$9 -> 7 | G9: =B9*D9 -> 149.4675 | H9: =B9*C9 -> 229.95 | I9: =B9*E9 -> 321.93
A10: Pre-order Pulled Pork /lb | B10: =Assumptions!$B$55 -> 18.99 | C10: 3 | D10: =C10*Assumptions!$B$7 -> 1.95 | E10: =C10*Assumptions!$B$9 -> 4.2 | G10: =B10*D10 -> 37.0305 | H10: =B10*C10 -> 56.97 | I10: =B10*E10 -> 79.758
A11: Pre-order Spare Ribs /rack | B11: =Assumptions!$B$56 -> 46.99 | C11: 2 | D11: =C11*Assumptions!$B$7 -> 1.3 | E11: =C11*Assumptions!$B$9 -> 2.8 | G11: =B11*D11 -> 61.087 | H11: =B11*C11 -> 93.98 | I11: =B11*E11 -> 131.572
A12: Pre-order Burnt Ends /lb | B12: =Assumptions!$B$57 -> 36.99 | C12: 2 | D12: =C12*Assumptions!$B$7 -> 1.3 | E12: =C12*Assumptions!$B$9 -> 2.8 | G12: =B12*D12 -> 48.087 | H12: =B12*C12 -> 73.98 | I12: =B12*E12 -> 103.572
A13: Pre-order Sausage /link | B13: =Assumptions!$B$58 -> 5.99 | C13: 6 | D13: =C13*Assumptions!$B$7 -> 3.9 | E13: =C13*Assumptions!$B$9 -> 8.4 | G13: =B13*D13 -> 23.361 | H13: =B13*C13 -> 35.94 | I13: =B13*E13 -> 50.316
A14: Pre-order Chicken LQ | B14: =Assumptions!$B$59 -> 7.99 | C14: 4 | D14: =C14*Assumptions!$B$7 -> 2.6 | E14: =C14*Assumptions!$B$9 -> 5.6 | G14: =B14*D14 -> 20.774 | H14: =B14*C14 -> 31.96 | I14: =B14*E14 -> 44.744
A15: Mac & Cheese 6 oz | B15: =Assumptions!$B$60 -> 5.99 | C15: 10 | D15: =C15*Assumptions!$B$7 -> 6.5 | E15: =C15*Assumptions!$B$9 -> 14 | G15: =B15*D15 -> 38.935 | H15: =B15*C15 -> 59.9 | I15: =B15*E15 -> 83.86
A16: Cowboy Beans 6 oz | B16: =Assumptions!$B$60 -> 5.99 | C16: 6 | D16: =C16*Assumptions!$B$7 -> 3.9 | E16: =C16*Assumptions!$B$9 -> 8.4 | G16: =B16*D16 -> 23.361 | H16: =B16*C16 -> 35.94 | I16: =B16*E16 -> 50.316
A17: Apple Slaw 6 oz | B17: =Assumptions!$B$60 -> 5.99 | C17: 4 | D17: =C17*Assumptions!$B$7 -> 2.6 | E17: =C17*Assumptions!$B$9 -> 5.6 | G17: =B17*D17 -> 15.574 | H17: =B17*C17 -> 23.96 | I17: =B17*E17 -> 33.544
A18: Banana Pudding | B18: =Assumptions!$B$61 -> 5.99 | C18: 12 | D18: =C18*Assumptions!$B$7 -> 7.8 | E18: =C18*Assumptions!$B$9 -> 16.8 | G18: =B18*D18 -> 46.722 | H18: =B18*C18 -> 71.88 | I18: =B18*E18 -> 100.632
A19: Fountain drink | B19: =Assumptions!$B$62 -> 2.99 | C19: 40 | D19: =C19*Assumptions!$B$7 -> 26 | E19: =C19*Assumptions!$B$9 -> 56 | G19: =B19*D19 -> 77.74 | H19: =B19*C19 -> 119.6 | I19: =B19*E19 -> 167.44
A20: Cornbread + tallow butter | B20: =Assumptions!$B$63 -> 2.99 | C20: 12 | D20: =C20*Assumptions!$B$7 -> 7.8 | E20: =C20*Assumptions!$B$9 -> 16.8 | G20: =B20*D20 -> 23.322 | H20: =B20*C20 -> 35.88 | I20: =B20*E20 -> 50.232
A21: Party Sampler Feeds 10 | B21: =Assumptions!$B$64 -> 289 | C21: 0.8 | D21: =C21*Assumptions!$B$7 -> 0.52 | E21: =C21*Assumptions!$B$9 -> 1.12 | G21: =B21*D21 -> 150.28 | H21: =B21*C21 -> 231.2 | I21: =B21*E21 -> 323.68
A22: Party Sampler Feeds 20 | B22: =Assumptions!$B$65 -> 570 | C22: 0.4 | D22: =C22*Assumptions!$B$7 -> 0.26 | E22: =C22*Assumptions!$B$9 -> 0.56 | G22: =B22*D22 -> 148.2 | H22: =B22*C22 -> 228 | I22: =B22*E22 -> 319.2
A23: Party Sampler Feeds 30 | B23: =Assumptions!$B$66 -> 825 | C23: 0.2 | D23: =C23*Assumptions!$B$7 -> 0.13 | E23: =C23*Assumptions!$B$9 -> 0.28 | G23: =B23*D23 -> 107.25 | H23: =B23*C23 -> 165 | I23: =B23*E23 -> 231
A24: Party Sampler Feeds 50 | B24: =Assumptions!$B$67 -> 1350 | C24: 0.1 | D24: =C24*Assumptions!$B$7 -> 0.065 | E24: =C24*Assumptions!$B$9 -> 0.14 | G24: =B24*D24 -> 87.75 | H24: =B24*C24 -> 135 | I24: =B24*E24 -> 189
A25: Daily sales | G25: =SUM(G5:G24) -> 2339.675 | H25: =SUM(H5:H24) -> 3599.5 | I25: =SUM(I5:I24) -> 5039.3
A26: Implied tickets / day at Seminole avg ticket | G26: =G25/Assumptions!$B$10 -> 49.993056 | H26: =H25/Assumptions!$B$10 -> 76.912393 | I26: =I25/Assumptions!$B$10 -> 107.67735
A27: Weekly sales | G27: =G25*Assumptions!$B$5 -> 11698.375 | H27: =H25*Assumptions!$B$5 -> 17997.5 | I27: =I25*Assumptions!$B$5 -> 25196.5
A28: Evening catering base: 4 Feeds-10, 2 Feeds-20, 1 Feeds-30 and 1 Feeds-50 every two weeks, picked up 2:30-7:00 pm (estimate - set your own target).
A29: Base units set so the base day (~$2,800) matches Seminole Heights Thu-Sat average ($2.1K-$2.9K/day, Sep 18-Oct 27) with walk-in à la carte removed and pre-orders added.
A31: Monthly P&L
G32: Conservative | H32: Base | I32: Strong
A33: Walk-in lunch (samplers, Cubans, sides, drinks) | G33: =(G5+G6+G7+G8+G15+G16+G17+G18+G19+G20)*Assumptions!$B$5*Assumptions!$B$6 -> 32613.3 | H33: =(H5+H6+H7+H8+H15+H16+H17+H18+H19+H20)*Assumptions!$B$5*Assumptions!$B$6 -> 50174.308 | I33: =(I5+I6+I7+I8+I15+I16+I17+I18+I19+I20)*Assumptions!$B$5*Assumptions!$B$6 -> 70244.031
A34: Pre-orders (meats by the pound, to-go window) | G34: =(G9+G10+G11+G12+G13+G14)*Assumptions!$B$5*Assumptions!$B$6 -> 7356.8215 | H34: =(H9+H10+H11+H12+H13+H14)*Assumptions!$B$5*Assumptions!$B$6 -> 11318.187 | I34: =(I9+I10+I11+I12+I13+I14)*Assumptions!$B$5*Assumptions!$B$6 -> 15845.462
A35: Evening catering pickups (Party Samplers, until 7 pm) | G35: =(G21+G22+G23+G24)*Assumptions!$B$5*Assumptions!$B$6 -> 10683.842 | H35: =(H21+H22+H23+H24)*Assumptions!$B$5*Assumptions!$B$6 -> 16436.68 | I35: =(I21+I22+I23+I24)*Assumptions!$B$5*Assumptions!$B$6 -> 23011.352
A36: Revenue | G36: =G25*Assumptions!$B$5*Assumptions!$B$6 -> 50653.964 | H36: =H25*Assumptions!$B$5*Assumptions!$B$6 -> 77929.175 | I36: =I25*Assumptions!$B$5*Assumptions!$B$6 -> 109100.85
A37: Meats (commissary transfer price) | G37: =(D5*'Menu Costing'!E40+D6*'Menu Costing'!F40+D7*'Menu Costing'!G40+D8*'Menu Costing'!H40+D9*'Menu Costing'!I40+D10*'Menu Costing'!J40+D11*'Menu Costing'!K40+D12*'Menu Costing'!L40+D13*'Menu Costing'!M40+D14*'Menu Costing'!N40+D15*'Menu Costing'!O40+D16*'Menu Costing'!P40+D17*'Menu Costing'!Q40+D18*'Menu Costing'!R40+D19*'Menu Costing'!S40+D20*'Menu Costing'!T40+D21*'Menu Costing'!U40+D22*'Menu Costing'!V40+D23*'Menu Costing'!W40+D24*'Menu Costing'!X40)*Assumptions!$B$5*Assumptions!$B$6 -> 10090.865 | H37: =(C5*'Menu Costing'!E40+C6*'Menu Costing'!F40+C7*'Menu Costing'!G40+C8*'Menu Costing'!H40+C9*'Menu Costing'!I40+C10*'Menu Costing'!J40+C11*'Menu Costing'!K40+C12*'Menu Costing'!L40+C13*'Menu Costing'!M40+C14*'Menu Costing'!N40+C15*'Menu Costing'!O40+C16*'Menu Costing'!P40+C17*'Menu Costing'!Q40+C18*'Menu Costing'!R40+C19*'Menu Costing'!S40+C20*'Menu Costing'!T40+C21*'Menu Costing'!U40+C22*'Menu Costing'!V40+C23*'Menu Costing'!W40+C24*'Menu Costing'!X40)*Assumptions!$B$5*Assumptions!$B$6 -> 15524.407 | I37: =(E5*'Menu Costing'!E40+E6*'Menu Costing'!F40+E7*'Menu Costing'!G40+E8*'Menu Costing'!H40+E9*'Menu Costing'!I40+E10*'Menu Costing'!J40+E11*'Menu Costing'!K40+E12*'Menu Costing'!L40+E13*'Menu Costing'!M40+E14*'Menu Costing'!N40+E15*'Menu Costing'!O40+E16*'Menu Costing'!P40+E17*'Menu Costing'!Q40+E18*'Menu Costing'!R40+E19*'Menu Costing'!S40+E20*'Menu Costing'!T40+E21*'Menu Costing'!U40+E22*'Menu Costing'!V40+E23*'Menu Costing'!W40+E24*'Menu Costing'!X40)*Assumptions!$B$5*Assumptions!$B$6 -> 21734.17
A38: Other food (sides, bread, deli, drinks) | G38: =(D5*'Menu Costing'!E41+D6*'Menu Costing'!F41+D7*'Menu Costing'!G41+D8*'Menu Costing'!H41+D9*'Menu Costing'!I41+D10*'Menu Costing'!J41+D11*'Menu Costing'!K41+D12*'Menu Costing'!L41+D13*'Menu Costing'!M41+D14*'Menu Costing'!N41+D15*'Menu Costing'!O41+D16*'Menu Costing'!P41+D17*'Menu Costing'!Q41+D18*'Menu Costing'!R41+D19*'Menu Costing'!S41+D20*'Menu Costing'!T41+D21*'Menu Costing'!U41+D22*'Menu Costing'!V41+D23*'Menu Costing'!W41+D24*'Menu Costing'!X41)*Assumptions!$B$5*Assumptions!$B$6 -> 5228.5623 | H38: =(C5*'Menu Costing'!E41+C6*'Menu Costing'!F41+C7*'Menu Costing'!G41+C8*'Menu Costing'!H41+C9*'Menu Costing'!I41+C10*'Menu Costing'!J41+C11*'Menu Costing'!K41+C12*'Menu Costing'!L41+C13*'Menu Costing'!M41+C14*'Menu Costing'!N41+C15*'Menu Costing'!O41+C16*'Menu Costing'!P41+C17*'Menu Costing'!Q41+C18*'Menu Costing'!R41+C19*'Menu Costing'!S41+C20*'Menu Costing'!T41+C21*'Menu Costing'!U41+C22*'Menu Costing'!V41+C23*'Menu Costing'!W41+C24*'Menu Costing'!X41)*Assumptions!$B$5*Assumptions!$B$6 -> 8043.942 | I38: =(E5*'Menu Costing'!E41+E6*'Menu Costing'!F41+E7*'Menu Costing'!G41+E8*'Menu Costing'!H41+E9*'Menu Costing'!I41+E10*'Menu Costing'!J41+E11*'Menu Costing'!K41+E12*'Menu Costing'!L41+E13*'Menu Costing'!M41+E14*'Menu Costing'!N41+E15*'Menu Costing'!O41+E16*'Menu Costing'!P41+E17*'Menu Costing'!Q41+E18*'Menu Costing'!R41+E19*'Menu Costing'!S41+E20*'Menu Costing'!T41+E21*'Menu Costing'!U41+E22*'Menu Costing'!V41+E23*'Menu Costing'!W41+E24*'Menu Costing'!X41)*Assumptions!$B$5*Assumptions!$B$6 -> 11261.519
A39: Packaging | G39: =(D5*'Menu Costing'!E42+D6*'Menu Costing'!F42+D7*'Menu Costing'!G42+D8*'Menu Costing'!H42+D9*'Menu Costing'!I42+D10*'Menu Costing'!J42+D11*'Menu Costing'!K42+D12*'Menu Costing'!L42+D13*'Menu Costing'!M42+D14*'Menu Costing'!N42+D15*'Menu Costing'!O42+D16*'Menu Costing'!P42+D17*'Menu Costing'!Q42+D18*'Menu Costing'!R42+D19*'Menu Costing'!S42+D20*'Menu Costing'!T42+D21*'Menu Costing'!U42+D22*'Menu Costing'!V42+D23*'Menu Costing'!W42+D24*'Menu Costing'!X42)*Assumptions!$B$5*Assumptions!$B$6 -> 1682.1436 | H39: =(C5*'Menu Costing'!E42+C6*'Menu Costing'!F42+C7*'Menu Costing'!G42+C8*'Menu Costing'!H42+C9*'Menu Costing'!I42+C10*'Menu Costing'!J42+C11*'Menu Costing'!K42+C12*'Menu Costing'!L42+C13*'Menu Costing'!M42+C14*'Menu Costing'!N42+C15*'Menu Costing'!O42+C16*'Menu Costing'!P42+C17*'Menu Costing'!Q42+C18*'Menu Costing'!R42+C19*'Menu Costing'!S42+C20*'Menu Costing'!T42+C21*'Menu Costing'!U42+C22*'Menu Costing'!V42+C23*'Menu Costing'!W42+C24*'Menu Costing'!X42)*Assumptions!$B$5*Assumptions!$B$6 -> 2587.9133 | I39: =(E5*'Menu Costing'!E42+E6*'Menu Costing'!F42+E7*'Menu Costing'!G42+E8*'Menu Costing'!H42+E9*'Menu Costing'!I42+E10*'Menu Costing'!J42+E11*'Menu Costing'!K42+E12*'Menu Costing'!L42+E13*'Menu Costing'!M42+E14*'Menu Costing'!N42+E15*'Menu Costing'!O42+E16*'Menu Costing'!P42+E17*'Menu Costing'!Q42+E18*'Menu Costing'!R42+E19*'Menu Costing'!S42+E20*'Menu Costing'!T42+E21*'Menu Costing'!U42+E22*'Menu Costing'!V42+E23*'Menu Costing'!W42+E24*'Menu Costing'!X42)*Assumptions!$B$5*Assumptions!$B$6 -> 3623.0786
A40: Waste / comps | G40: =(G37+G38)*Assumptions!$B$99 -> 459.58281 | H40: =(H37+H38)*Assumptions!$B$99 -> 707.05048 | I40: =(I37+I38)*Assumptions!$B$99 -> 989.87067
A41: Total cost of goods | G41: =SUM(G37:G40) -> 17461.154 | H41: =SUM(H37:H40) -> 26863.313 | I41: =SUM(I37:I40) -> 37608.638
A42: COGS % of sales | G42: =IF(G36=0,0,G41/G36) -> 0.34471446 | H42: =IF(H36=0,0,H41/H36) -> 0.34471446 | I42: =IF(I36=0,0,I41/I36) -> 0.34471446
...

Sheet Break-Even
A1: Break-even
A2: Fixed costs divided by contribution margin. Uses the Base scenario cost structure.
A4: Fixed monthly costs
A5: Labor (GM + crew + payroll taxes) | B5: ='Sales & P&L'!$H$48 -> 16123.86 | D5: Treated as fixed: a lunch-only crew is scheduled the same every day.
A6: Occupancy (rent, NNN, utilities) | B6: ='Sales & P&L'!$H$54 -> 9300
A7: Fixed operating (insurance, software, linens, repairs, etc.) | B7: ='Sales & P&L'!$H$67-'Sales & P&L'!$H$55-'Sales & P&L'!$H$56 -> 3524.75
A8: Total fixed costs per month | B8: =B5+B6+B7 -> 28948.61
A10: Variable costs (% of sales, Base mix)
A11: Cost of goods % | B11: ='Sales & P&L'!$H$41/'Sales & P&L'!$H$36 -> 0.34471446
A12: Card processing % | B12: =Assumptions!$B$97 -> 0.029
A13: Marketing % | B13: =Assumptions!$B$98 -> 0.02
A14: Contribution margin % | B14: =1-B11-B12-B13 -> 0.60628554
A16: Break-even sales
A17: Break-even sales per month | B17: =B8/B14 -> 47747.485
A18: Break-even sales per week | B18: =B17/Assumptions!$B$6 -> 11027.133 | D18: Compare: Anthony's rule of thumb for retail is ~$10K/week to be worth opening.
A19: Break-even sales per day open | B19: =B18/Assumptions!$B$5 -> 2205.4266
A20: Break-even tickets per day (at $46.80 avg ticket) | B20: =B19/Assumptions!$B$10 -> 47.124499
A21: Same thing in 5-Alarm 2-3 Samplers per day | B21: =B19/Assumptions!$B$50 -> 36.763237 | D21: If every dollar came from 2-3 samplers - a way to picture the number.
A22: Base-scenario daily sales | B22: ='Sales & P&L'!$H$25 -> 3599.5
A23: Cushion: base day above break-even | B23: =B22/B19-1 -> 0.63211057
A25: Break-even including an investor return
A26: Target investor cash return (annual % of startup cost) | B26: 0.2 | D26: Input. Investor split is undecided; 20%/yr = 5-year simple payback.
A27: Investor return per month | B27: ='Startup Budget'!$F$50*B26/12 -> 7770.2319
A28: Break-even sales per day incl. investor return | B28: =(B8+B27)/B14/Assumptions!$B$6/Assumptions!$B$5 -> 2797.3954

Sheet Startup Budget
A1: Startup budget: raw shell (1st gen) vs former restaurant (2nd gen)
A2: Equipment priced new from online dealers (Oct 2026); expect 10-20% off list. A 2nd-generation space already has a hood, grease trap, plumbing and often a walk-in, so build-out drops sharply.
A4: Category | B4: Item | C4: Model / spec | D4: Qty | E4: Unit price | F4: 1st gen (raw shell) | G4: 2nd gen (former restaurant) | I4: Source / note
A5: Cooking | B5: Double-stack combi oven (2 ovens) | C5: Rational iCombi Pro 6-full, electric 208/240V 3-ph, 42" x 41" | D5: 2 | E5: 22656 | F5: =D5*E5 -> 45312 | G5: =F5 -> 45312 | I5: WebstaurantStore list $22,656 each (login price lower). 62A each - needs 3-phase service.
A6: Cooking | B6: Combi stacking kit | C6: Rational Combi-Duo 60.76.575 | D6: 1 | E6: 1300 | F6: =D6*E6 -> 1300 | G6: =F6 -> 1300 | I6: CA$1,715 (Chef Supplies); US price not found - estimate.
A7: Cooking | B7: Cook & hold cabinets (stacked) | C7: Alto-Shaam 1200-TH, 240 lb capacity, 208-240V 1-ph | D7: 2 | E7: 12533 | F7: =D7*E7 -> 25066 | G7: =F7 -> 25066 | I7: KaTom $12,532.74 each; stacked to save line space. 1000-TH/I-QS is $10,726 if smaller works.
A8: Cooking | B8: On-site smoker (daily fresh chicken) | C8: Cookshack FEC120 pellet smoker, 120V, 46.5" x 35", ~30 whole chickens/load | D8: 1 | E8: 11800 | F8: =D8*E8 -> 11800 | G8: =F8 -> 11800 | I8: KaTom $11,800; cULus listed. Goes under the Type I hood - confirm with the fire inspector.
A9: Cooking | B9: Tilting steam kettle, 20 gal | C9: Vulcan K20ETT tabletop, electric 208V 3-ph | D9: 1 | E9: 20014 | F9: =D9*E9 -> 20014 | G9: =F9 -> 20014 | I9: KaTom $20,014. Floor model K20ELT $29,481. Used Cleveland KEL20T $4,497 but 480V.
A10: Cooking | B10: Griddle + 2-burner range (no fryer) | C10: Vulcan 36S-2B24GT: 24" griddle, 2 burners, oven base, nat gas, 36" x 34" | D10: 1 | E10: 9132 | F10: =D10*E10 -> 9132 | G10: =F10 -> 9132 | I10: KaTom $9,132 (list $22,183).
A11: Cooking | B11: Cuban / sandwich press | C11: Waring WPG300 double, grooved cast iron, 240V | D11: 2 | E11: 1015 | F11: =D11*E11 -> 2030 | G11: =F11 -> 2030 | I11: KaTom $1,015 each; used $475 at City Food Equipment.
A12: Service line | B12: Carving station w/ 2 heat lamps | C12: Hatco DCSB400-3624-2, 36" x 24" board | D12: 1 | E12: 3994 | F12: =D12*E12 -> 3994 | G12: =F12 -> 3994 | I12: City Food Equipment $3,994.
A13: Service line | B13: 4-well hot food table + cold rail | C13: Electric 4-well + sneeze guard | D13: 1 | E13: 2800 | F13: =D13*E13 -> 2800 | G13: =F13 -> 2800 | I13: Estimate - no sourced price.
A14: Service line | B14: To-go heated pickup shelf | C14: Heated shelf / pass-thru, 3 tier | D14: 1 | E14: 1800 | F14: =D14*E14 -> 1800 | G14: =F14 -> 1800 | I14: Estimate.
A15: Refrigeration | B15: Walk-in cooler 8 x 10 | C15: Imperial Brown IB810C | D15: 1 | E15: 20886 | F15: =D15*E15 -> 20886 | G15: 0 | I15: KaTom $20,886. 2nd gen: Assumes the space has a usable walk-in.
A16: Refrigeration | B16: Walk-in install | C16: Set, refrigeration line, electrical | D16: 1 | E16: 4000 | F16: =D16*E16 -> 4000 | G16: 2500 | I16: Estimate. 2nd gen: Service / re-gas existing walk-in (estimate).
A17: Refrigeration | B17: Sandwich prep cooler | C17: 48"-60" refrigerated prep table | D17: 1 | E17: 3384 | F17: =D17*E17 -> 3384 | G17: =F17 -> 3384 | I17: Top of $1,649-$3,384 range (The Restaurant Warehouse).
A18: Refrigeration | B18: Reach-in / drink cooler | C18: True T-49 2-section | D18: 1 | E18: 7491 | F18: =D18*E18 -> 7491 | G18: =F18 -> 7491 | I18: KaTom $7,491.
A19: Refrigeration | B19: Ice machine + bin | C19: Manitowoc IRP0500W, 500 lb/day, 365 lb bin | D19: 1 | E19: 6395 | F19: =D19*E19 -> 6395 | G19: =F19 -> 6395 | I19: HVAC Pro Sales $6,395 (W = water-cooled; confirm).
A20: Sinks & prep | B20: 3-compartment sink | C20: Regency 72.5" 16-ga | D20: 1 | E20: 569 | F20: =D20*E20 -> 569 | G20: 0 | I20: WebstaurantStore listing (unconfirmed). 2nd gen: Usually in place.
A21: Sinks & prep | B21: Hand sinks | C21: Advance Tabco 7-PS-EC-SP-X | D21: 3 | E21: 361 | F21: =D21*E21 -> 1083 | G21: 0 | I21: KaTom $361 each. 2nd gen: Usually in place.
A22: Sinks & prep | B22: Prep sink + mop sink | D22: 1 | E22: 900 | F22: =D22*E22 -> 900 | G22: 0 | I22: Estimate. 2nd gen: Usually in place.
A23: Sinks & prep | B23: Stainless prep tables 30 x 60 | C23: Steelton 16-ga | D23: 2 | E23: 189 | F23: =D23*E23 -> 378 | G23: =F23 -> 378 | I23: WebstaurantStore $189 each.
A24: Sinks & prep | B24: Shelving (dry storage + walk-in) | C24: NSF wire shelving units | D24: 8 | E24: 180 | F24: =D24*E24 -> 1440 | G24: =F24 -> 1440 | I24: Estimate.
A25: Ventilation | B25: Type I hood, 16 ft, installed | C25: Over smoker, griddle, kettle, combi | D25: 16 | E25: 1100 | F25: =D25*E25 -> 17600 | G25: 9500 | I25: $950-$1,200 per linear ft installed (Ambient Edge); national, not FL-specific. 2nd gen: Reuse existing hood and extend ~4 ft for the smoker, re-balance (estimate).
A26: Ventilation | B26: Fire suppression | C26: ANSUL R-102, 16 ft hood (extra nozzles for smoker) | D26: 1 | E26: 12000 | F26: =D26*E26 -> 12000 | G26: 1500 | I26: ThePricer ~$10,419 for 10 ft hardware + install; +~$1,600 estimate for 16 ft. Before permits. 2nd gen: Recertify / re-nozzle existing system (estimate).
A27: Front of house | B27: Square POS register + kiosk + 2 KDS | C27: Register $1,799, kiosk ~$1,500, KDS $900 x2 | D27: 1 | E27: 5099 | F27: =D27*E27 -> 5099 | G27: =F27 -> 5099 | I27: UpMenu May 2026 Square pricing article; kiosk estimate.
A28: Front of house | B28: Tables, chairs, window bar, stools | C28: 6 four-tops, 24 chairs, bar, 8 stools | D28: 1 | E28: 8500 | F28: =D28*E28 -> 8500 | G28: =F28 -> 8500 | I28: Estimate.
A29: Front of house | B29: 5-Alarm effect: beacon, siren, controller, brass bell | C29: Feniex light bar + controller + siren + bell | D29: 1 | E29: 3550 | F29: =D29*E29 -> 3550 | G29: =F29 -> 3550 | I29: Feniex: light bar up to $1,899, controller up to $1,099, siren up to $299; bell estimate $250.
A30: Front of house | B30: Signage, logo sign, fire pole, decor | C30: Incl. helmet shelf + bunker gear display | D30: 1 | E30: 13500 | F30: =D30*E30 -> 13500 | G30: =F30 -> 13500 | I30: Estimate; used turnout gear and helmets run ~$100-$400 per piece.
A31: Smallwares | B31: Smallwares (pans, knives, boards, cambros) | D31: 1 | E31: 8000 | F31: =D31*E31 -> 8000 | G31: =F31 -> 8000 | I31: Estimate - no sourced figure.
B32: Equipment subtotal | F32: =SUM(F5:F31) -> 238023 | G32: =SUM(G5:G31) -> 194485
A34: Build-out, soft costs and pre-opening
A35: Build-out | B35: Tenant improvements (walls, floors, plumbing, electrical, restrooms) | C35: $/sq ft x 1,500 | D35: 1500 | E35: 175 | F35: =D35*E35 -> 262500 | G35: =D35*60 -> 90000 | I35: 1st gen: raw shell restaurant build-outs commonly run $150-$300/sf (estimate). 2nd gen: refresh finishes, minor plumbing/electrical at ~$60/sf (estimate). A landlord TI allowance reduces either.
A36: Build-out | B36: 3-phase electrical service upgrade | D36: 1 | E36: 0 | F36: =D36*E36 -> 0 | G36: 8000 | I36: 1st gen: included in TI. 2nd gen: combi + kettle need 3-phase; budget an upgrade if the space lacks it (estimate).
A37: Build-out | B37: Grease interceptor | D37: 1 | E37: 15000 | F37: =D37*E37 -> 15000 | G37: 500 | I37: 1st gen: new in-ground interceptor (estimate). 2nd gen: existing - pump and inspect.
A38: Soft costs | B38: Architect, engineering, permits, impact fees | D38: 1 | E38: 25000 | F38: =D38*E38 -> 25000 | G38: 12000 | I38: Estimate. 2nd gen is often a change-of-use or alteration permit only.
A39: Pre-opening | B39: Security deposit + first month (rent + NNN) | D39: 2 | E39: =Assumptions!$B$84+Assumptions!$B$85 -> 7500 | F39: =D39*E39 -> 15000 | G39: =F39 -> 15000 | I39: Formula: 2 x (rent + NNN).
A40: Pre-opening | B40: Pre-opening labor (training, 2 weeks) | D40: 1 | E40: 8000 | F40: =D40*E40 -> 8000 | G40: =F40 -> 8000 | I40: Estimate.
A41: Pre-opening | B41: Opening inventory (non-meat) + packaging | D41: 1 | E41: 4000 | F41: =D41*E41 -> 4000 | G41: =F41 -> 4000 | I41: Estimate.
A42: Pre-opening | B42: Grand opening marketing | D42: 1 | E42: 5000 | F42: =D42*E42 -> 5000 | G42: =F42 -> 5000 | I42: Estimate.
...

Sheet Prep List
A1: Daily prep list (par levels)
A2: Forecast use = menu-item quantities x forecast units, plus the prep buffer. Pick the scenario column that matches the day.
A4: Component | B4: Unit | C4: Conservative day | D4: Base day | E4: Strong day | F4: Base: prep as | G4: How / when | H4: Prep unit
A5: Brisket (sliced) | B5: cooked lb | C5: =('Menu Costing'!E5*'Sales & P&L'!D5+'Menu Costing'!F5*'Sales & P&L'!D6+'Menu Costing'!G5*'Sales & P&L'!D7+'Menu Costing'!I5*'Sales & P&L'!D9+'Menu Costing'!U5*'Sales & P&L'!D21+'Menu Costing'!V5*'Sales & P&L'!D22+'Menu Costing'!W5*'Sales & P&L'!D23+'Menu Costing'!X5*'Sales & P&L'!D24)*(1+Assumptions!$B$48) -> 13.013 | D5: =('Menu Costing'!E5*'Sales & P&L'!C5+'Menu Costing'!F5*'Sales & P&L'!C6+'Menu Costing'!G5*'Sales & P&L'!C7+'Menu Costing'!I5*'Sales & P&L'!C9+'Menu Costing'!U5*'Sales & P&L'!C21+'Menu Costing'!V5*'Sales & P&L'!C22+'Menu Costing'!W5*'Sales & P&L'!C23+'Menu Costing'!X5*'Sales & P&L'!C24)*(1+Assumptions!$B$48) -> 20.02 | E5: =('Menu Costing'!E5*'Sales & P&L'!E5+'Menu Costing'!F5*'Sales & P&L'!E6+'Menu Costing'!G5*'Sales & P&L'!E7+'Menu Costing'!I5*'Sales & P&L'!E9+'Menu Costing'!U5*'Sales & P&L'!E21+'Menu Costing'!V5*'Sales & P&L'!E22+'Menu Costing'!W5*'Sales & P&L'!E23+'Menu Costing'!X5*'Sales & P&L'!E24)*(1+Assumptions!$B$48) -> 28.028 | F5: =D5/(Assumptions!$B$39*Assumptions!$B$46) -> 2.86 | G5: Pull vac-packs from walk-in 8:30; combi reheat to 165F, hold in Alto-Shaam. Slice to order only. | H5: packers
A6: Pulled pork | B6: cooked lb | C6: =('Menu Costing'!E6*'Sales & P&L'!D5+'Menu Costing'!F6*'Sales & P&L'!D6+'Menu Costing'!H6*'Sales & P&L'!D8+'Menu Costing'!J6*'Sales & P&L'!D10+'Menu Costing'!U6*'Sales & P&L'!D21+'Menu Costing'!V6*'Sales & P&L'!D22+'Menu Costing'!W6*'Sales & P&L'!D23+'Menu Costing'!X6*'Sales & P&L'!D24)*(1+Assumptions!$B$48) -> 13.897813 | D6: =('Menu Costing'!E6*'Sales & P&L'!C5+'Menu Costing'!F6*'Sales & P&L'!C6+'Menu Costing'!H6*'Sales & P&L'!C8+'Menu Costing'!J6*'Sales & P&L'!C10+'Menu Costing'!U6*'Sales & P&L'!C21+'Menu Costing'!V6*'Sales & P&L'!C22+'Menu Costing'!W6*'Sales & P&L'!C23+'Menu Costing'!X6*'Sales & P&L'!C24)*(1+Assumptions!$B$48) -> 21.38125 | E6: =('Menu Costing'!E6*'Sales & P&L'!E5+'Menu Costing'!F6*'Sales & P&L'!E6+'Menu Costing'!H6*'Sales & P&L'!E8+'Menu Costing'!J6*'Sales & P&L'!E10+'Menu Costing'!U6*'Sales & P&L'!E21+'Menu Costing'!V6*'Sales & P&L'!E22+'Menu Costing'!W6*'Sales & P&L'!E23+'Menu Costing'!X6*'Sales & P&L'!E24)*(1+Assumptions!$B$48) -> 29.93375 | F6: =D6 -> 21.38125 | G6: Reheat in combi with jus, hold in Alto-Shaam; pull for Cubans and samplers. | H6: lb cooked
A7: Burnt ends | B7: cooked lb | C7: =('Menu Costing'!L7*'Sales & P&L'!D12)*(1+Assumptions!$B$48) -> 1.43 | D7: =('Menu Costing'!L7*'Sales & P&L'!C12)*(1+Assumptions!$B$48) -> 2.2 | E7: =('Menu Costing'!L7*'Sales & P&L'!E12)*(1+Assumptions!$B$48) -> 3.08 | F7: =D7 -> 2.2 | G7: Pre-orders only: reheat and glaze to order. | H7: lb cooked
A8: Spare rib (bone) | B8: bone | C8: =('Menu Costing'!E8*'Sales & P&L'!D5+'Menu Costing'!F8*'Sales & P&L'!D6+'Menu Costing'!K8*'Sales & P&L'!D11+'Menu Costing'!U8*'Sales & P&L'!D21+'Menu Costing'!V8*'Sales & P&L'!D22+'Menu Costing'!W8*'Sales & P&L'!D23+'Menu Costing'!X8*'Sales & P&L'!D24)*(1+Assumptions!$B$48) -> 61.204 | D8: =('Menu Costing'!E8*'Sales & P&L'!C5+'Menu Costing'!F8*'Sales & P&L'!C6+'Menu Costing'!K8*'Sales & P&L'!C11+'Menu Costing'!U8*'Sales & P&L'!C21+'Menu Costing'!V8*'Sales & P&L'!C22+'Menu Costing'!W8*'Sales & P&L'!C23+'Menu Costing'!X8*'Sales & P&L'!C24)*(1+Assumptions!$B$48) -> 94.16 | E8: =('Menu Costing'!E8*'Sales & P&L'!E5+'Menu Costing'!F8*'Sales & P&L'!E6+'Menu Costing'!K8*'Sales & P&L'!E11+'Menu Costing'!U8*'Sales & P&L'!E21+'Menu Costing'!V8*'Sales & P&L'!E22+'Menu Costing'!W8*'Sales & P&L'!E23+'Menu Costing'!X8*'Sales & P&L'!E24)*(1+Assumptions!$B$48) -> 131.824 | F8: =D8/Assumptions!$B$43 -> 7.8466667 | G8: Reheat racks in combi, hold wrapped; cut to bones at cutting station. | H8: racks
A9: Chicken leg quarter | B9: each | C9: =('Menu Costing'!E9*'Sales & P&L'!D5+'Menu Costing'!F9*'Sales & P&L'!D6+'Menu Costing'!N9*'Sales & P&L'!D14+'Menu Costing'!U9*'Sales & P&L'!D21+'Menu Costing'!V9*'Sales & P&L'!D22+'Menu Costing'!W9*'Sales & P&L'!D23+'Menu Costing'!X9*'Sales & P&L'!D24)*(1+Assumptions!$B$48) -> 22.9515 | D9: =('Menu Costing'!E9*'Sales & P&L'!C5+'Menu Costing'!F9*'Sales & P&L'!C6+'Menu Costing'!N9*'Sales & P&L'!C14+'Menu Costing'!U9*'Sales & P&L'!C21+'Menu Costing'!V9*'Sales & P&L'!C22+'Menu Costing'!W9*'Sales & P&L'!C23+'Menu Costing'!X9*'Sales & P&L'!C24)*(1+Assumptions!$B$48) -> 35.31 | E9: =('Menu Costing'!E9*'Sales & P&L'!E5+'Menu Costing'!F9*'Sales & P&L'!E6+'Menu Costing'!N9*'Sales & P&L'!E14+'Menu Costing'!U9*'Sales & P&L'!E21+'Menu Costing'!V9*'Sales & P&L'!E22+'Menu Costing'!W9*'Sales & P&L'!E23+'Menu Costing'!X9*'Sales & P&L'!E24)*(1+Assumptions!$B$48) -> 49.434 | F9: =D9 -> 35.31 | G9: Smoked fresh daily in the store smoker: load 7:30, ready ~10:30, into Alto-Shaam. | H9: pieces
A10: Jalapeno cheddar sausage | B10: link | C10: =('Menu Costing'!E10*'Sales & P&L'!D5+'Menu Costing'!F10*'Sales & P&L'!D6+'Menu Costing'!M10*'Sales & P&L'!D13+'Menu Costing'!U10*'Sales & P&L'!D21+'Menu Costing'!V10*'Sales & P&L'!D22+'Menu Costing'!W10*'Sales & P&L'!D23+'Menu Costing'!X10*'Sales & P&L'!D24)*(1+Assumptions!$B$48) -> 26.312 | D10: =('Menu Costing'!E10*'Sales & P&L'!C5+'Menu Costing'!F10*'Sales & P&L'!C6+'Menu Costing'!M10*'Sales & P&L'!C13+'Menu Costing'!U10*'Sales & P&L'!C21+'Menu Costing'!V10*'Sales & P&L'!C22+'Menu Costing'!W10*'Sales & P&L'!C23+'Menu Costing'!X10*'Sales & P&L'!C24)*(1+Assumptions!$B$48) -> 40.48 | E10: =('Menu Costing'!E10*'Sales & P&L'!E5+'Menu Costing'!F10*'Sales & P&L'!E6+'Menu Costing'!M10*'Sales & P&L'!E13+'Menu Costing'!U10*'Sales & P&L'!E21+'Menu Costing'!V10*'Sales & P&L'!E22+'Menu Costing'!W10*'Sales & P&L'!E23+'Menu Costing'!X10*'Sales & P&L'!E24)*(1+Assumptions!$B$48) -> 56.672 | F10: =D10 -> 40.48 | G10: Reheat in combi, hold. | H10: links
A11: Mac & cheese | B11: oz | C11: =('Menu Costing'!E11*'Sales & P&L'!D5+'Menu Costing'!F11*'Sales & P&L'!D6+'Menu Costing'!O11*'Sales & P&L'!D15+'Menu Costing'!U11*'Sales & P&L'!D21+'Menu Costing'!V11*'Sales & P&L'!D22+'Menu Costing'!W11*'Sales & P&L'!D23+'Menu Costing'!X11*'Sales & P&L'!D24)*(1+Assumptions!$B$48) -> 411.268 | D11: =('Menu Costing'!E11*'Sales & P&L'!C5+'Menu Costing'!F11*'Sales & P&L'!C6+'Menu Costing'!O11*'Sales & P&L'!C15+'Menu Costing'!U11*'Sales & P&L'!C21+'Menu Costing'!V11*'Sales & P&L'!C22+'Menu Costing'!W11*'Sales & P&L'!C23+'Menu Costing'!X11*'Sales & P&L'!C24)*(1+Assumptions!$B$48) -> 632.72 | E11: =('Menu Costing'!E11*'Sales & P&L'!E5+'Menu Costing'!F11*'Sales & P&L'!E6+'Menu Costing'!O11*'Sales & P&L'!E15+'Menu Costing'!U11*'Sales & P&L'!E21+'Menu Costing'!V11*'Sales & P&L'!E22+'Menu Costing'!W11*'Sales & P&L'!E23+'Menu Costing'!X11*'Sales & P&L'!E24)*(1+Assumptions!$B$48) -> 885.808 | F11: =D11/'Sides & Ingredients'!$E$25 -> 2.4715625 | G11: Kettle, 9:00. Hold in hot well; second batch at 12:00 if Strong. | H11: batches (2 gal)
A12: Cowboy beans | B12: oz | C12: =('Menu Costing'!E12*'Sales & P&L'!D5+'Menu Costing'!F12*'Sales & P&L'!D6+'Menu Costing'!P12*'Sales & P&L'!D16+'Menu Costing'!U12*'Sales & P&L'!D21+'Menu Costing'!V12*'Sales & P&L'!D22+'Menu Costing'!W12*'Sales & P&L'!D23+'Menu Costing'!X12*'Sales & P&L'!D24)*(1+Assumptions!$B$48) -> 231.66 | D12: =('Menu Costing'!E12*'Sales & P&L'!C5+'Menu Costing'!F12*'Sales & P&L'!C6+'Menu Costing'!P12*'Sales & P&L'!C16+'Menu Costing'!U12*'Sales & P&L'!C21+'Menu Costing'!V12*'Sales & P&L'!C22+'Menu Costing'!W12*'Sales & P&L'!C23+'Menu Costing'!X12*'Sales & P&L'!C24)*(1+Assumptions!$B$48) -> 356.4 | E12: =('Menu Costing'!E12*'Sales & P&L'!E5+'Menu Costing'!F12*'Sales & P&L'!E6+'Menu Costing'!P12*'Sales & P&L'!E16+'Menu Costing'!U12*'Sales & P&L'!E21+'Menu Costing'!V12*'Sales & P&L'!E22+'Menu Costing'!W12*'Sales & P&L'!E23+'Menu Costing'!X12*'Sales & P&L'!E24)*(1+Assumptions!$B$48) -> 498.96 | F12: =D12/'Sides & Ingredients'!$E$38 -> 1.0482353 | G12: Kettle after mac. Hold in hot well. | H12: batches
A13: Apple coleslaw | B13: oz | C13: =('Menu Costing'!Q13*'Sales & P&L'!D17+'Menu Costing'!U13*'Sales & P&L'!D21+'Menu Costing'!V13*'Sales & P&L'!D22+'Menu Costing'!W13*'Sales & P&L'!D23+'Menu Costing'!X13*'Sales & P&L'!D24)*(1+Assumptions!$B$48) -> 108.68 | D13: =('Menu Costing'!Q13*'Sales & P&L'!C17+'Menu Costing'!U13*'Sales & P&L'!C21+'Menu Costing'!V13*'Sales & P&L'!C22+'Menu Costing'!W13*'Sales & P&L'!C23+'Menu Costing'!X13*'Sales & P&L'!C24)*(1+Assumptions!$B$48) -> 167.2 | E13: =('Menu Costing'!Q13*'Sales & P&L'!E17+'Menu Costing'!U13*'Sales & P&L'!E21+'Menu Costing'!V13*'Sales & P&L'!E22+'Menu Costing'!W13*'Sales & P&L'!E23+'Menu Costing'!X13*'Sales & P&L'!E24)*(1+Assumptions!$B$48) -> 234.08 | F13: =D13/'Sides & Ingredients'!$E$50 -> 1.045 | G13: Mix fresh daily; cold rail. | H13: batches
A14: Banana pudding | B14: cup | C14: =('Menu Costing'!R14*'Sales & P&L'!D18)*(1+Assumptions!$B$48) -> 8.58 | D14: =('Menu Costing'!R14*'Sales & P&L'!C18)*(1+Assumptions!$B$48) -> 13.2 | E14: =('Menu Costing'!R14*'Sales & P&L'!E18)*(1+Assumptions!$B$48) -> 18.48 | F14: =D14/'Sides & Ingredients'!$E$61 -> 0.55 | G14: Day before; cups in reach-in. | H14: batches (24)
A15: Texas toast | B15: slice | C15: =('Menu Costing'!E15*'Sales & P&L'!D5+'Menu Costing'!F15*'Sales & P&L'!D6+'Menu Costing'!U15*'Sales & P&L'!D21+'Menu Costing'!V15*'Sales & P&L'!D22+'Menu Costing'!W15*'Sales & P&L'!D23+'Menu Costing'!X15*'Sales & P&L'!D24)*(1+Assumptions!$B$48) -> 91.52 | D15: =('Menu Costing'!E15*'Sales & P&L'!C5+'Menu Costing'!F15*'Sales & P&L'!C6+'Menu Costing'!U15*'Sales & P&L'!C21+'Menu Costing'!V15*'Sales & P&L'!C22+'Menu Costing'!W15*'Sales & P&L'!C23+'Menu Costing'!X15*'Sales & P&L'!C24)*(1+Assumptions!$B$48) -> 140.8 | E15: =('Menu Costing'!E15*'Sales & P&L'!E5+'Menu Costing'!F15*'Sales & P&L'!E6+'Menu Costing'!U15*'Sales & P&L'!E21+'Menu Costing'!V15*'Sales & P&L'!E22+'Menu Costing'!W15*'Sales & P&L'!E23+'Menu Costing'!X15*'Sales & P&L'!E24)*(1+Assumptions!$B$48) -> 197.12 | F15: =D15/20 -> 7.04 | G15: Toast to order on griddle. | H15: loaves (20 sl)
A16: Pickles | B16: oz | C16: =('Menu Costing'!E16*'Sales & P&L'!D5+'Menu Costing'!F16*'Sales & P&L'!D6+'Menu Costing'!U16*'Sales & P&L'!D21+'Menu Costing'!V16*'Sales & P&L'!D22+'Menu Costing'!W16*'Sales & P&L'!D23+'Menu Costing'!X16*'Sales & P&L'!D24)*(1+Assumptions!$B$48) -> 30.316 | D16: =('Menu Costing'!E16*'Sales & P&L'!C5+'Menu Costing'!F16*'Sales & P&L'!C6+'Menu Costing'!U16*'Sales & P&L'!C21+'Menu Costing'!V16*'Sales & P&L'!C22+'Menu Costing'!W16*'Sales & P&L'!C23+'Menu Costing'!X16*'Sales & P&L'!C24)*(1+Assumptions!$B$48) -> 46.64 | E16: =('Menu Costing'!E16*'Sales & P&L'!E5+'Menu Costing'!F16*'Sales & P&L'!E6+'Menu Costing'!U16*'Sales & P&L'!E21+'Menu Costing'!V16*'Sales & P&L'!E22+'Menu Costing'!W16*'Sales & P&L'!E23+'Menu Costing'!X16*'Sales & P&L'!E24)*(1+Assumptions!$B$48) -> 65.296 | F16: =D16 -> 46.64 | G16: Portion into 1 oz cups. | H16: oz
A17: Pickled onions | B17: oz | C17: =('Menu Costing'!E17*'Sales & P&L'!D5+'Menu Costing'!F17*'Sales & P&L'!D6+'Menu Costing'!G17*'Sales & P&L'!D7+'Menu Costing'!U17*'Sales & P&L'!D21+'Menu Costing'!V17*'Sales & P&L'!D22+'Menu Costing'!W17*'Sales & P&L'!D23+'Menu Costing'!X17*'Sales & P&L'!D24)*(1+Assumptions!$B$48) -> 34.749 | D17: =('Menu Costing'!E17*'Sales & P&L'!C5+'Menu Costing'!F17*'Sales & P&L'!C6+'Menu Costing'!G17*'Sales & P&L'!C7+'Menu Costing'!U17*'Sales & P&L'!C21+'Menu Costing'!V17*'Sales & P&L'!C22+'Menu Costing'!W17*'Sales & P&L'!C23+'Menu Costing'!X17*'Sales & P&L'!C24)*(1+Assumptions!$B$48) -> 53.46 | E17: =('Menu Costing'!E17*'Sales & P&L'!E5+'Menu Costing'!F17*'Sales & P&L'!E6+'Menu Costing'!G17*'Sales & P&L'!E7+'Menu Costing'!U17*'Sales & P&L'!E21+'Menu Costing'!V17*'Sales & P&L'!E22+'Menu Costing'!W17*'Sales & P&L'!E23+'Menu Costing'!X17*'Sales & P&L'!E24)*(1+Assumptions!$B$48) -> 74.844 | F17: =D17/'Sides & Ingredients'!$E$71 -> 0.66825 | G17: 2x per week. | H17: batches
A18: BBQ sauce | B18: oz | C18: =('Menu Costing'!E18*'Sales & P&L'!D5+'Menu Costing'!F18*'Sales & P&L'!D6+'Menu Costing'!I18*'Sales & P&L'!D9+'Menu Costing'!J18*'Sales & P&L'!D10+'Menu Costing'!K18*'Sales & P&L'!D11+'Menu Costing'!U18*'Sales & P&L'!D21+'Menu Costing'!V18*'Sales & P&L'!D22+'Menu Costing'!W18*'Sales & P&L'!D23+'Menu Costing'!X18*'Sales & P&L'!D24)*(1+Assumptions!$B$48) -> 119.262 | D18: =('Menu Costing'!E18*'Sales & P&L'!C5+'Menu Costing'!F18*'Sales & P&L'!C6+'Menu Costing'!I18*'Sales & P&L'!C9+'Menu Costing'!J18*'Sales & P&L'!C10+'Menu Costing'!K18*'Sales & P&L'!C11+'Menu Costing'!U18*'Sales & P&L'!C21+'Menu Costing'!V18*'Sales & P&L'!C22+'Menu Costing'!W18*'Sales & P&L'!C23+'Menu Costing'!X18*'Sales & P&L'!C24)*(1+Assumptions!$B$48) -> 183.48 | E18: =('Menu Costing'!E18*'Sales & P&L'!E5+'Menu Costing'!F18*'Sales & P&L'!E6+'Menu Costing'!I18*'Sales & P&L'!E9+'Menu Costing'!J18*'Sales & P&L'!E10+'Menu Costing'!K18*'Sales & P&L'!E11+'Menu Costing'!U18*'Sales & P&L'!E21+'Menu Costing'!V18*'Sales & P&L'!E22+'Menu Costing'!W18*'Sales & P&L'!E23+'Menu Costing'!X18*'Sales & P&L'!E24)*(1+Assumptions!$B$48) -> 256.872 | F18: =D18/128 -> 1.4334375 | G18: Portion 2 oz cups; 3 per sampler. | H18: gal
A19: Cuban bread | B19: each | C19: =('Menu Costing'!G19*'Sales & P&L'!D7+'Menu Costing'!H19*'Sales & P&L'!D8)*(1+Assumptions!$B$48) -> 33.605 | D19: =('Menu Costing'!G19*'Sales & P&L'!C7+'Menu Costing'!H19*'Sales & P&L'!C8)*(1+Assumptions!$B$48) -> 51.7 | E19: =('Menu Costing'!G19*'Sales & P&L'!E7+'Menu Costing'!H19*'Sales & P&L'!E8)*(1+Assumptions!$B$48) -> 72.38 | F19: =D19 -> 51.7 | G19: Bakery delivery daily 8:00. | H19: loaves
A20: Swiss | B20: oz | C20: =('Menu Costing'!G20*'Sales & P&L'!D7+'Menu Costing'!H20*'Sales & P&L'!D8)*(1+Assumptions!$B$48) -> 50.4075 | D20: =('Menu Costing'!G20*'Sales & P&L'!C7+'Menu Costing'!H20*'Sales & P&L'!C8)*(1+Assumptions!$B$48) -> 77.55 | E20: =('Menu Costing'!G20*'Sales & P&L'!E7+'Menu Costing'!H20*'Sales & P&L'!E8)*(1+Assumptions!$B$48) -> 108.57 | F20: =D20/16 -> 4.846875 | H20: lb
A21: Ham | B21: oz | C21: =('Menu Costing'!H21*'Sales & P&L'!D8)*(1+Assumptions!$B$48) -> 35.75 | D21: =('Menu Costing'!H21*'Sales & P&L'!C8)*(1+Assumptions!$B$48) -> 55 | E21: =('Menu Costing'!H21*'Sales & P&L'!E8)*(1+Assumptions!$B$48) -> 77 | F21: =D21/16 -> 3.4375 | H21: lb
A22: Salami | B22: oz | C22: =('Menu Costing'!H22*'Sales & P&L'!D8)*(1+Assumptions!$B$48) -> 17.875 | D22: =('Menu Costing'!H22*'Sales & P&L'!C8)*(1+Assumptions!$B$48) -> 27.5 | E22: =('Menu Costing'!H22*'Sales & P&L'!E8)*(1+Assumptions!$B$48) -> 38.5 | F22: =D22/16 -> 1.71875 | H22: lb
